[2025-10-31T18:38:31.648+0000] {taskinstance.py:1956} INFO - Dependencies all met for dep_context=non-requeueable deps ti=<TaskInstance: validate_csv.validate_csv manual__2025-10-31T18:38:26.026710+00:00 [queued]>
[2025-10-31T18:38:31.682+0000] {taskinstance.py:1956} INFO - Dependencies all met for dep_context=requeueable deps ti=<TaskInstance: validate_csv.validate_csv manual__2025-10-31T18:38:26.026710+00:00 [queued]>
[2025-10-31T18:38:31.684+0000] {taskinstance.py:2170} INFO - Starting attempt 1 of 1
[2025-10-31T18:38:31.744+0000] {taskinstance.py:2191} INFO - Executing <Task(PythonOperator): validate_csv> on 2025-10-31 18:38:26.026710+00:00
[2025-10-31T18:38:31.766+0000] {standard_task_runner.py:60} INFO - Started process 232 to run task
[2025-10-31T18:38:31.847+0000] {standard_task_runner.py:87} INFO - Running: ['***', 'tasks', 'run', 'validate_csv', 'validate_csv', 'manual__2025-10-31T18:38:26.026710+00:00', '--job-id', '10', '--raw', '--subdir', 'DAGS_FOLDER/validate.py', '--cfg-path', '/tmp/tmpq3o3wcnf']
[2025-10-31T18:38:31.853+0000] {standard_task_runner.py:88} INFO - Job 10: Subtask validate_csv
[2025-10-31T18:38:32.055+0000] {task_command.py:423} INFO - Running <TaskInstance: validate_csv.validate_csv manual__2025-10-31T18:38:26.026710+00:00 [running]> on host e13be8f86677
[2025-10-31T18:38:33.016+0000] {taskinstance.py:2480} INFO - Exporting env vars: AIRFLOW_CTX_DAG_OWNER='***' AIRFLOW_CTX_DAG_ID='validate_csv' AIRFLOW_CTX_TASK_ID='validate_csv' AIRFLOW_CTX_EXECUTION_DATE='2025-10-31T18:38:26.026710+00:00' AIRFLOW_CTX_TRY_NUMBER='1' AIRFLOW_CTX_DAG_RUN_ID='manual__2025-10-31T18:38:26.026710+00:00'
[2025-10-31T18:38:33.091+0000] {taskinstance.py:2698} ERROR - Task failed with exception
Traceback (most recent call last):
  File "/home/airflow/.local/lib/python3.8/site-packages/airflow/models/taskinstance.py", line 433, in _execute_task
    result = execute_callable(context=context, **execute_callable_kwargs)
  File "/home/airflow/.local/lib/python3.8/site-packages/airflow/operators/python.py", line 199, in execute
    return_value = self.execute_callable()
  File "/home/airflow/.local/lib/python3.8/site-packages/airflow/operators/python.py", line 216, in execute_callable
    return self.python_callable(*self.op_args, **self.op_kwargs)
  File "/opt/airflow/dags/validate.py", line 13, in validate_csv
    df = pd.read_csv(data, sep=";", engine="python", dtype=str, encoding='latin2', on_bad_lines='skip')
  File "/home/airflow/.local/lib/python3.8/site-packages/pandas/io/parsers/readers.py", line 912, in read_csv
    return _read(filepath_or_buffer, kwds)
  File "/home/airflow/.local/lib/python3.8/site-packages/pandas/io/parsers/readers.py", line 577, in _read
    parser = TextFileReader(filepath_or_buffer, **kwds)
  File "/home/airflow/.local/lib/python3.8/site-packages/pandas/io/parsers/readers.py", line 1407, in __init__
    self._engine = self._make_engine(f, self.engine)
  File "/home/airflow/.local/lib/python3.8/site-packages/pandas/io/parsers/readers.py", line 1661, in _make_engine
    self.handles = get_handle(
  File "/home/airflow/.local/lib/python3.8/site-packages/pandas/io/common.py", line 859, in get_handle
    handle = open(
FileNotFoundError: [Errno 2] No such file or directory: 'data/mtr_test_2.csv'
[2025-10-31T18:38:33.248+0000] {taskinstance.py:1138} INFO - Marking task as FAILED. dag_id=validate_csv, task_id=validate_csv, execution_date=20251031T183826, start_date=20251031T183831, end_date=20251031T183833
[2025-10-31T18:38:33.324+0000] {standard_task_runner.py:107} ERROR - Failed to execute job 10 for task validate_csv ([Errno 2] No such file or directory: 'data/mtr_test_2.csv'; 232)
[2025-10-31T18:38:33.399+0000] {local_task_job_runner.py:234} INFO - Task exited with return code 1
[2025-10-31T18:38:33.477+0000] {taskinstance.py:3280} INFO - 0 downstream tasks scheduled from follow-on schedule check
