[2025-11-01T16:55:31.411+0000] {taskinstance.py:1956} INFO - Dependencies all met for dep_context=non-requeueable deps ti=<TaskInstance: load_csv_to_clickhouse.load_csv_to_clickhouse manual__2025-11-01T16:55:29.327447+00:00 [queued]>
[2025-11-01T16:55:31.435+0000] {taskinstance.py:1956} INFO - Dependencies all met for dep_context=requeueable deps ti=<TaskInstance: load_csv_to_clickhouse.load_csv_to_clickhouse manual__2025-11-01T16:55:29.327447+00:00 [queued]>
[2025-11-01T16:55:31.437+0000] {taskinstance.py:2170} INFO - Starting attempt 1 of 1
[2025-11-01T16:55:31.488+0000] {taskinstance.py:2191} INFO - Executing <Task(PythonOperator): load_csv_to_clickhouse> on 2025-11-01 16:55:29.327447+00:00
[2025-11-01T16:55:31.516+0000] {standard_task_runner.py:60} INFO - Started process 260 to run task
[2025-11-01T16:55:31.529+0000] {standard_task_runner.py:87} INFO - Running: ['***', 'tasks', 'run', 'load_csv_to_clickhouse', 'load_csv_to_clickhouse', 'manual__2025-11-01T16:55:29.327447+00:00', '--job-id', '15', '--raw', '--subdir', 'DAGS_FOLDER/load_to_clickhouse.py', '--cfg-path', '/tmp/tmp6kfumdx_']
[2025-11-01T16:55:31.537+0000] {standard_task_runner.py:88} INFO - Job 15: Subtask load_csv_to_clickhouse
[2025-11-01T16:55:31.734+0000] {task_command.py:423} INFO - Running <TaskInstance: load_csv_to_clickhouse.load_csv_to_clickhouse manual__2025-11-01T16:55:29.327447+00:00 [running]> on host 4944221c0f0f
[2025-11-01T16:55:32.781+0000] {taskinstance.py:2480} INFO - Exporting env vars: AIRFLOW_CTX_DAG_OWNER='***' AIRFLOW_CTX_DAG_ID='load_csv_to_clickhouse' AIRFLOW_CTX_TASK_ID='load_csv_to_clickhouse' AIRFLOW_CTX_EXECUTION_DATE='2025-11-01T16:55:29.327447+00:00' AIRFLOW_CTX_TRY_NUMBER='1' AIRFLOW_CTX_DAG_RUN_ID='manual__2025-11-01T16:55:29.327447+00:00'
[2025-11-01T16:55:33.536+0000] {taskinstance.py:2698} ERROR - Task failed with exception
Traceback (most recent call last):
  File "/home/airflow/.local/lib/python3.8/site-packages/airflow/models/taskinstance.py", line 433, in _execute_task
    result = execute_callable(context=context, **execute_callable_kwargs)
  File "/home/airflow/.local/lib/python3.8/site-packages/airflow/operators/python.py", line 199, in execute
    return_value = self.execute_callable()
  File "/home/airflow/.local/lib/python3.8/site-packages/airflow/operators/python.py", line 216, in execute_callable
    return self.python_callable(*self.op_args, **self.op_kwargs)
  File "/opt/airflow/dags/load_to_clickhouse.py", line 29, in load_csv_to_clickhouse
    client.execute(
  File "/home/airflow/.local/lib/python3.8/site-packages/clickhouse_driver/client.py", line 376, in execute
    rv = self.process_insert_query(
  File "/home/airflow/.local/lib/python3.8/site-packages/clickhouse_driver/client.py", line 607, in process_insert_query
    rv = self.send_data(sample_block, data,
  File "/home/airflow/.local/lib/python3.8/site-packages/clickhouse_driver/client.py", line 658, in send_data
    block = block_cls(sample_block.columns_with_types, chunk,
  File "/home/airflow/.local/lib/python3.8/site-packages/clickhouse_driver/block.py", line 40, in __init__
    self.data = self.normalize(data or [])
  File "/home/airflow/.local/lib/python3.8/site-packages/clickhouse_driver/block.py", line 128, in normalize
    self._mutate_dicts_to_rows(data)
  File "/home/airflow/.local/lib/python3.8/site-packages/clickhouse_driver/block.py", line 159, in _mutate_dicts_to_rows
    return self._pure_mutate_dicts_to_rows(
  File "/home/airflow/.local/lib/python3.8/site-packages/clickhouse_driver/block.py", line 186, in _pure_mutate_dicts_to_rows
    new_data.append(row[name])
KeyError: 'registrikood'
[2025-11-01T16:55:33.592+0000] {taskinstance.py:1138} INFO - Marking task as FAILED. dag_id=load_csv_to_clickhouse, task_id=load_csv_to_clickhouse, execution_date=20251101T165529, start_date=20251101T165531, end_date=20251101T165533
[2025-11-01T16:55:33.628+0000] {standard_task_runner.py:107} ERROR - Failed to execute job 15 for task load_csv_to_clickhouse ('registrikood'; 260)
[2025-11-01T16:55:33.685+0000] {local_task_job_runner.py:234} INFO - Task exited with return code 1
[2025-11-01T16:55:33.735+0000] {taskinstance.py:3280} INFO - 0 downstream tasks scheduled from follow-on schedule check
