[2025-10-31T20:25:21.179+0000] {taskinstance.py:1956} INFO - Dependencies all met for dep_context=non-requeueable deps ti=<TaskInstance: load_csv_to_clickhouse.load_csv_to_clickhouse manual__2025-10-31T20:25:18.479357+00:00 [queued]>
[2025-10-31T20:25:21.199+0000] {taskinstance.py:1956} INFO - Dependencies all met for dep_context=requeueable deps ti=<TaskInstance: load_csv_to_clickhouse.load_csv_to_clickhouse manual__2025-10-31T20:25:18.479357+00:00 [queued]>
[2025-10-31T20:25:21.200+0000] {taskinstance.py:2170} INFO - Starting attempt 1 of 1
[2025-10-31T20:25:21.231+0000] {taskinstance.py:2191} INFO - Executing <Task(PythonOperator): load_csv_to_clickhouse> on 2025-10-31 20:25:18.479357+00:00
[2025-10-31T20:25:21.260+0000] {standard_task_runner.py:60} INFO - Started process 196 to run task
[2025-10-31T20:25:21.279+0000] {standard_task_runner.py:87} INFO - Running: ['***', 'tasks', 'run', 'load_csv_to_clickhouse', 'load_csv_to_clickhouse', 'manual__2025-10-31T20:25:18.479357+00:00', '--job-id', '22', '--raw', '--subdir', 'DAGS_FOLDER/load_to_clickhouse.py', '--cfg-path', '/tmp/tmp7wrvg_kx']
[2025-10-31T20:25:21.288+0000] {standard_task_runner.py:88} INFO - Job 22: Subtask load_csv_to_clickhouse
[2025-10-31T20:25:21.487+0000] {task_command.py:423} INFO - Running <TaskInstance: load_csv_to_clickhouse.load_csv_to_clickhouse manual__2025-10-31T20:25:18.479357+00:00 [running]> on host e13be8f86677
[2025-10-31T20:25:21.874+0000] {taskinstance.py:2480} INFO - Exporting env vars: AIRFLOW_CTX_DAG_OWNER='***' AIRFLOW_CTX_DAG_ID='load_csv_to_clickhouse' AIRFLOW_CTX_TASK_ID='load_csv_to_clickhouse' AIRFLOW_CTX_EXECUTION_DATE='2025-10-31T20:25:18.479357+00:00' AIRFLOW_CTX_TRY_NUMBER='1' AIRFLOW_CTX_DAG_RUN_ID='manual__2025-10-31T20:25:18.479357+00:00'
[2025-10-31T20:25:26.005+0000] {connection.py:411} WARNING - Failed to connect to clickhouse:9000
Traceback (most recent call last):
  File "/home/airflow/.local/lib/python3.8/site-packages/clickhouse_driver/connection.py", line 399, in connect
    return self._init_connection(host, port)
  File "/home/airflow/.local/lib/python3.8/site-packages/clickhouse_driver/connection.py", line 329, in _init_connection
    self.socket = self._create_socket(host, port)
  File "/home/airflow/.local/lib/python3.8/site-packages/clickhouse_driver/connection.py", line 280, in _create_socket
    for res in socket.getaddrinfo(host, port, 0, socket.SOCK_STREAM):
  File "/usr/local/lib/python3.8/socket.py", line 918, in getaddrinfo
    for res in _socket.getaddrinfo(host, port, family, type, proto, flags):
socket.gaierror: [Errno -2] Name or service not known
[2025-10-31T20:25:26.012+0000] {taskinstance.py:2698} ERROR - Task failed with exception
Traceback (most recent call last):
  File "/home/airflow/.local/lib/python3.8/site-packages/airflow/models/taskinstance.py", line 433, in _execute_task
    result = execute_callable(context=context, **execute_callable_kwargs)
  File "/home/airflow/.local/lib/python3.8/site-packages/airflow/operators/python.py", line 199, in execute
    return_value = self.execute_callable()
  File "/home/airflow/.local/lib/python3.8/site-packages/airflow/operators/python.py", line 216, in execute_callable
    return self.python_callable(*self.op_args, **self.op_kwargs)
  File "/opt/airflow/dags/load_to_clickhouse.py", line 19, in load_csv_to_clickhouse
    client.execute(f"ALTER TABLE bronze_mtr_raw DELETE WHERE allikas = 'MTR_{date_str}.csv'")
  File "/home/airflow/.local/lib/python3.8/site-packages/clickhouse_driver/client.py", line 370, in execute
    with self.disconnect_on_error(query, settings):
  File "/usr/local/lib/python3.8/contextlib.py", line 113, in __enter__
    return next(self.gen)
  File "/home/airflow/.local/lib/python3.8/site-packages/clickhouse_driver/client.py", line 313, in disconnect_on_error
    self.establish_connection(settings)
  File "/home/airflow/.local/lib/python3.8/site-packages/clickhouse_driver/client.py", line 300, in establish_connection
    self.connection.force_connect()
  File "/home/airflow/.local/lib/python3.8/site-packages/clickhouse_driver/connection.py", line 258, in force_connect
    self.connect()
  File "/home/airflow/.local/lib/python3.8/site-packages/clickhouse_driver/connection.py", line 420, in connect
    raise err
clickhouse_driver.errors.NetworkError: Code: 210. Name or service not known (clickhouse:9000)
[2025-10-31T20:25:26.070+0000] {taskinstance.py:1138} INFO - Marking task as FAILED. dag_id=load_csv_to_clickhouse, task_id=load_csv_to_clickhouse, execution_date=20251031T202518, start_date=20251031T202521, end_date=20251031T202526
[2025-10-31T20:25:26.107+0000] {standard_task_runner.py:107} ERROR - Failed to execute job 22 for task load_csv_to_clickhouse (Code: 210. Name or service not known (clickhouse:9000); 196)
[2025-10-31T20:25:26.195+0000] {local_task_job_runner.py:234} INFO - Task exited with return code 1
[2025-10-31T20:25:26.238+0000] {taskinstance.py:3280} INFO - 0 downstream tasks scheduled from follow-on schedule check
