[2025-11-01T18:32:57.061+0000] {taskinstance.py:1956} INFO - Dependencies all met for dep_context=non-requeueable deps ti=<TaskInstance: validate_csv.validate_csv manual__2025-11-01T18:32:29.641577+00:00 [queued]>
[2025-11-01T18:32:57.091+0000] {taskinstance.py:1956} INFO - Dependencies all met for dep_context=requeueable deps ti=<TaskInstance: validate_csv.validate_csv manual__2025-11-01T18:32:29.641577+00:00 [queued]>
[2025-11-01T18:32:57.092+0000] {taskinstance.py:2170} INFO - Starting attempt 1 of 1
[2025-11-01T18:32:57.140+0000] {taskinstance.py:2191} INFO - Executing <Task(PythonOperator): validate_csv> on 2025-11-01 18:32:29.641577+00:00
[2025-11-01T18:32:57.168+0000] {standard_task_runner.py:60} INFO - Started process 193 to run task
[2025-11-01T18:32:57.177+0000] {standard_task_runner.py:87} INFO - Running: ['***', 'tasks', 'run', 'validate_csv', 'validate_csv', 'manual__2025-11-01T18:32:29.641577+00:00', '--job-id', '40', '--raw', '--subdir', 'DAGS_FOLDER/validate.py', '--cfg-path', '/tmp/tmpryqtb8kk']
[2025-11-01T18:32:57.184+0000] {standard_task_runner.py:88} INFO - Job 40: Subtask validate_csv
[2025-11-01T18:32:57.387+0000] {task_command.py:423} INFO - Running <TaskInstance: validate_csv.validate_csv manual__2025-11-01T18:32:29.641577+00:00 [running]> on host 5fa557a7832a
[2025-11-01T18:32:57.692+0000] {taskinstance.py:2480} INFO - Exporting env vars: AIRFLOW_CTX_DAG_OWNER='***' AIRFLOW_CTX_DAG_ID='validate_csv' AIRFLOW_CTX_TASK_ID='validate_csv' AIRFLOW_CTX_EXECUTION_DATE='2025-11-01T18:32:29.641577+00:00' AIRFLOW_CTX_TRY_NUMBER='1' AIRFLOW_CTX_DAG_RUN_ID='manual__2025-11-01T18:32:29.641577+00:00'
[2025-11-01T18:32:57.717+0000] {taskinstance.py:2698} ERROR - Task failed with exception
Traceback (most recent call last):
  File "/home/airflow/.local/lib/python3.8/site-packages/airflow/models/taskinstance.py", line 433, in _execute_task
    result = execute_callable(context=context, **execute_callable_kwargs)
  File "/home/airflow/.local/lib/python3.8/site-packages/airflow/operators/python.py", line 199, in execute
    return_value = self.execute_callable()
  File "/home/airflow/.local/lib/python3.8/site-packages/airflow/operators/python.py", line 216, in execute_callable
    return self.python_callable(*self.op_args, **self.op_kwargs)
  File "/opt/airflow/dags/validate.py", line 13, in validate_csv
    df = pd.read_csv(data, sep=";", engine="python", dtype=str, encoding='utf-8', on_bad_lines='skip')
  File "/home/airflow/.local/lib/python3.8/site-packages/pandas/io/parsers/readers.py", line 912, in read_csv
    return _read(filepath_or_buffer, kwds)
  File "/home/airflow/.local/lib/python3.8/site-packages/pandas/io/parsers/readers.py", line 577, in _read
    parser = TextFileReader(filepath_or_buffer, **kwds)
  File "/home/airflow/.local/lib/python3.8/site-packages/pandas/io/parsers/readers.py", line 1407, in __init__
    self._engine = self._make_engine(f, self.engine)
  File "/home/airflow/.local/lib/python3.8/site-packages/pandas/io/parsers/readers.py", line 1679, in _make_engine
    return mapping[engine](f, **self.options)
  File "/home/airflow/.local/lib/python3.8/site-packages/pandas/io/parsers/python_parser.py", line 124, in __init__
    ) = self._infer_columns()
  File "/home/airflow/.local/lib/python3.8/site-packages/pandas/io/parsers/python_parser.py", line 397, in _infer_columns
    line = self._buffered_line()
  File "/home/airflow/.local/lib/python3.8/site-packages/pandas/io/parsers/python_parser.py", line 630, in _buffered_line
    return self._next_line()
  File "/home/airflow/.local/lib/python3.8/site-packages/pandas/io/parsers/python_parser.py", line 731, in _next_line
    orig_line = self._next_iter_line(row_num=self.pos + 1)
  File "/home/airflow/.local/lib/python3.8/site-packages/pandas/io/parsers/python_parser.py", line 795, in _next_iter_line
    line = next(self.data)
  File "/usr/local/lib/python3.8/codecs.py", line 322, in decode
    (result, consumed) = self._buffer_decode(data, self.errors, final)
UnicodeDecodeError: 'utf-8' codec can't decode byte 0xdc in position 128: invalid continuation byte
[2025-11-01T18:32:57.759+0000] {taskinstance.py:1138} INFO - Marking task as FAILED. dag_id=validate_csv, task_id=validate_csv, execution_date=20251101T183229, start_date=20251101T183257, end_date=20251101T183257
[2025-11-01T18:32:58.944+0000] {standard_task_runner.py:107} ERROR - Failed to execute job 40 for task validate_csv ('utf-8' codec can't decode byte 0xdc in position 128: invalid continuation byte; 193)
[2025-11-01T18:32:59.010+0000] {local_task_job_runner.py:234} INFO - Task exited with return code 1
[2025-11-01T18:32:59.069+0000] {taskinstance.py:3280} INFO - 0 downstream tasks scheduled from follow-on schedule check
